[2017-04-18 23:15:04 +0800] [5181] [INFO] Starting gunicorn 19.7.1
[2017-04-18 23:15:04 +0800] [5181] [INFO] Listening at: http://0.0.0.0:80 (5181)
[2017-04-18 23:15:04 +0800] [5181] [INFO] Using worker: sync
[2017-04-18 23:15:04 +0800] [5184] [INFO] Booting worker with pid: 5184
[2017-04-18 23:15:04 +0800] [5185] [INFO] Booting worker with pid: 5185
[2017-04-18 23:15:04 +0800] [5186] [INFO] Booting worker with pid: 5186
[2017-04-18 23:15:04 +0800] [5187] [INFO] Booting worker with pid: 5187
[2017-04-18 23:15:08 +0800] [5184] [ERROR] Exception in worker process
Traceback (most recent call last):
  File "/usr/local/lib/python3.5/dist-packages/gunicorn/arbiter.py", line 578, in spawn_worker
    worker.init_process()
  File "/usr/local/lib/python3.5/dist-packages/gunicorn/workers/base.py", line 126, in init_process
    self.load_wsgi()
  File "/usr/local/lib/python3.5/dist-packages/gunicorn/workers/base.py", line 135, in load_wsgi
    self.wsgi = self.app.wsgi()
  File "/usr/local/lib/python3.5/dist-packages/gunicorn/app/base.py", line 67, in wsgi
    self.callable = self.load()
  File "/usr/local/lib/python3.5/dist-packages/gunicorn/app/wsgiapp.py", line 65, in load
    return self.load_wsgiapp()
  File "/usr/local/lib/python3.5/dist-packages/gunicorn/app/wsgiapp.py", line 52, in load_wsgiapp
    return util.import_app(self.app_uri)
  File "/usr/local/lib/python3.5/dist-packages/gunicorn/util.py", line 352, in import_app
    __import__(module)
  File "/root/Share_All/Flask_virsion/app.py", line 207, in <module>
    app.run(host='0.0.0.0', port=80)
  File "/root/.local/lib/python3.5/site-packages/flask/app.py", line 841, in run
    run_simple(host, port, self, **options)
  File "/root/.local/lib/python3.5/site-packages/werkzeug/serving.py", line 736, in run_simple
    inner()
  File "/root/.local/lib/python3.5/site-packages/werkzeug/serving.py", line 696, in inner
    fd=fd)
  File "/root/.local/lib/python3.5/site-packages/werkzeug/serving.py", line 590, in make_server
    passthrough_errors, ssl_context, fd=fd)
  File "/root/.local/lib/python3.5/site-packages/werkzeug/serving.py", line 501, in __init__
    HTTPServer.__init__(self, (host, int(port)), handler)
  File "/usr/lib/python3.5/socketserver.py", line 441, in __init__
    self.server_activate()
  File "/usr/lib/python3.5/socketserver.py", line 463, in server_activate
    self.socket.listen(self.request_queue_size)
OSError: [Errno 98] Address already in use
[2017-04-18 23:15:08 +0800] [5184] [INFO] Worker exiting (pid: 5184)
[2017-04-18 23:15:08 +0800] [5185] [ERROR] Exception in worker process
Traceback (most recent call last):
  File "/usr/local/lib/python3.5/dist-packages/gunicorn/arbiter.py", line 578, in spawn_worker
    worker.init_process()
  File "/usr/local/lib/python3.5/dist-packages/gunicorn/workers/base.py", line 126, in init_process
    self.load_wsgi()
  File "/usr/local/lib/python3.5/dist-packages/gunicorn/workers/base.py", line 135, in load_wsgi
    self.wsgi = self.app.wsgi()
  File "/usr/local/lib/python3.5/dist-packages/gunicorn/app/base.py", line 67, in wsgi
    self.callable = self.load()
  File "/usr/local/lib/python3.5/dist-packages/gunicorn/app/wsgiapp.py", line 65, in load
    return self.load_wsgiapp()
  File "/usr/local/lib/python3.5/dist-packages/gunicorn/app/wsgiapp.py", line 52, in load_wsgiapp
    return util.import_app(self.app_uri)
  File "/usr/local/lib/python3.5/dist-packages/gunicorn/util.py", line 352, in import_app
    __import__(module)
  File "/root/Share_All/Flask_virsion/app.py", line 207, in <module>
    app.run(host='0.0.0.0', port=80)
  File "/root/.local/lib/python3.5/site-packages/flask/app.py", line 841, in run
    run_simple(host, port, self, **options)
  File "/root/.local/lib/python3.5/site-packages/werkzeug/serving.py", line 736, in run_simple
    inner()
  File "/root/.local/lib/python3.5/site-packages/werkzeug/serving.py", line 696, in inner
    fd=fd)
  File "/root/.local/lib/python3.5/site-packages/werkzeug/serving.py", line 590, in make_server
    passthrough_errors, ssl_context, fd=fd)
  File "/root/.local/lib/python3.5/site-packages/werkzeug/serving.py", line 501, in __init__
    HTTPServer.__init__(self, (host, int(port)), handler)
  File "/usr/lib/python3.5/socketserver.py", line 441, in __init__
    self.server_activate()
  File "/usr/lib/python3.5/socketserver.py", line 463, in server_activate
    self.socket.listen(self.request_queue_size)
OSError: [Errno 98] Address already in use
[2017-04-18 23:15:08 +0800] [5185] [INFO] Worker exiting (pid: 5185)
[2017-04-18 23:15:08 +0800] [5186] [ERROR] Exception in worker process
Traceback (most recent call last):
  File "/usr/local/lib/python3.5/dist-packages/gunicorn/arbiter.py", line 578, in spawn_worker
    worker.init_process()
  File "/usr/local/lib/python3.5/dist-packages/gunicorn/workers/base.py", line 126, in init_process
    self.load_wsgi()
  File "/usr/local/lib/python3.5/dist-packages/gunicorn/workers/base.py", line 135, in load_wsgi
    self.wsgi = self.app.wsgi()
  File "/usr/local/lib/python3.5/dist-packages/gunicorn/app/base.py", line 67, in wsgi
    self.callable = self.load()
  File "/usr/local/lib/python3.5/dist-packages/gunicorn/app/wsgiapp.py", line 65, in load
    return self.load_wsgiapp()
  File "/usr/local/lib/python3.5/dist-packages/gunicorn/app/wsgiapp.py", line 52, in load_wsgiapp
    return util.import_app(self.app_uri)
  File "/usr/local/lib/python3.5/dist-packages/gunicorn/util.py", line 352, in import_app
    __import__(module)
  File "/root/Share_All/Flask_virsion/app.py", line 207, in <module>
    app.run(host='0.0.0.0', port=80)
  File "/root/.local/lib/python3.5/site-packages/flask/app.py", line 841, in run
    run_simple(host, port, self, **options)
  File "/root/.local/lib/python3.5/site-packages/werkzeug/serving.py", line 736, in run_simple
    inner()
  File "/root/.local/lib/python3.5/site-packages/werkzeug/serving.py", line 696, in inner
    fd=fd)
  File "/root/.local/lib/python3.5/site-packages/werkzeug/serving.py", line 590, in make_server
    passthrough_errors, ssl_context, fd=fd)
  File "/root/.local/lib/python3.5/site-packages/werkzeug/serving.py", line 501, in __init__
    HTTPServer.__init__(self, (host, int(port)), handler)
  File "/usr/lib/python3.5/socketserver.py", line 441, in __init__
    self.server_activate()
  File "/usr/lib/python3.5/socketserver.py", line 463, in server_activate
    self.socket.listen(self.request_queue_size)
OSError: [Errno 98] Address already in use
[2017-04-18 23:15:08 +0800] [5186] [INFO] Worker exiting (pid: 5186)
[2017-04-18 23:15:08 +0800] [5187] [ERROR] Exception in worker process
Traceback (most recent call last):
  File "/usr/local/lib/python3.5/dist-packages/gunicorn/arbiter.py", line 578, in spawn_worker
    worker.init_process()
  File "/usr/local/lib/python3.5/dist-packages/gunicorn/workers/base.py", line 126, in init_process
    self.load_wsgi()
  File "/usr/local/lib/python3.5/dist-packages/gunicorn/workers/base.py", line 135, in load_wsgi
    self.wsgi = self.app.wsgi()
  File "/usr/local/lib/python3.5/dist-packages/gunicorn/app/base.py", line 67, in wsgi
    self.callable = self.load()
  File "/usr/local/lib/python3.5/dist-packages/gunicorn/app/wsgiapp.py", line 65, in load
    return self.load_wsgiapp()
  File "/usr/local/lib/python3.5/dist-packages/gunicorn/app/wsgiapp.py", line 52, in load_wsgiapp
    return util.import_app(self.app_uri)
  File "/usr/local/lib/python3.5/dist-packages/gunicorn/util.py", line 352, in import_app
    __import__(module)
  File "/root/Share_All/Flask_virsion/app.py", line 207, in <module>
    app.run(host='0.0.0.0', port=80)
  File "/root/.local/lib/python3.5/site-packages/flask/app.py", line 841, in run
    run_simple(host, port, self, **options)
  File "/root/.local/lib/python3.5/site-packages/werkzeug/serving.py", line 736, in run_simple
    inner()
  File "/root/.local/lib/python3.5/site-packages/werkzeug/serving.py", line 696, in inner
    fd=fd)
  File "/root/.local/lib/python3.5/site-packages/werkzeug/serving.py", line 590, in make_server
    passthrough_errors, ssl_context, fd=fd)
  File "/root/.local/lib/python3.5/site-packages/werkzeug/serving.py", line 501, in __init__
    HTTPServer.__init__(self, (host, int(port)), handler)
  File "/usr/lib/python3.5/socketserver.py", line 441, in __init__
    self.server_activate()
  File "/usr/lib/python3.5/socketserver.py", line 463, in server_activate
    self.socket.listen(self.request_queue_size)
OSError: [Errno 98] Address already in use
[2017-04-18 23:15:08 +0800] [5187] [INFO] Worker exiting (pid: 5187)
[2017-04-18 23:15:09 +0800] [5181] [INFO] Shutting down: Master
[2017-04-18 23:15:09 +0800] [5181] [INFO] Reason: Worker failed to boot.
